<?xml version="1.0" encoding="utf-8"?>
<!-- This URDF was automatically created by SolidWorks to URDF Exporter! Originally created by Stephen Brawner (brawner@gmail.com) 
     Commit Version: 1.6.0-4-g7f85cfe  Build Version: 1.6.7995.38578
     For more information, please see http://wiki.ros.org/sw_urdf_exporter -->
<robot
  name="Vertical_ver">
  <link
    name="base_link">
    <inertial>
      <origin
        xyz="0 2.7756E-17 0"
        rpy="0 0 0" />
      <mass
        value="8.1509" />
      <inertia
        ixx="0.068891"
        ixy="-9.9636E-19"
        ixz="-1.8735E-19"
        iyy="0.013503"
        iyz="1.9516E-18"
        izz="0.068891" />
    </inertial>
    <visual>
      <origin
        xyz="0 0 0"
        rpy="0 0 0" />
      <geometry>
        <mesh
          filename="package://Vertical_ver/meshes/base_link.STL" />
      </geometry>
      <material
        name="">
        <color
          rgba="0.89804 0.91765 0.92941 1" />
      </material>
    </visual>
    <collision>
      <origin
        xyz="0 0 0"
        rpy="0 0 0" />
      <geometry>
        <mesh
          filename="package://Vertical_ver/meshes/base_link.STL" />
      </geometry>
    </collision>
  </link>
  <link
    name="left_thigh_link">
    <inertial>
      <origin
        xyz="0.15 2.7756E-17 -0.005"
        rpy="0 0 0" />
      <mass
        value="0.43749" />
      <inertia
        ixx="9.5683E-05"
        ixy="-6.1175E-21"
        ixz="8.9336E-22"
        iyy="0.0039485"
        iyz="-8.0974E-22"
        izz="0.0040369" />
    </inertial>
    <visual>
      <origin
        xyz="0 0 0"
        rpy="0 0 0" />
      <geometry>
        <mesh
          filename="package://Vertical_ver/meshes/left_thigh_link.STL" />
      </geometry>
      <material
        name="">
        <color
          rgba="0.89804 0.91765 0.92941 1" />
      </material>
    </visual>
    <collision>
      <origin
        xyz="0 0 0"
        rpy="0 0 0" />
      <geometry>
        <mesh
          filename="package://Vertical_ver/meshes/left_thigh_link.STL" />
      </geometry>
    </collision>
  </link>
  <joint
    name="left_thigh_joint"
    type="revolute">
    <origin
      xyz="0 0.18 0"
      rpy="1.5708 1.5708 0" />
    <parent
      link="base_link" />
    <child
      link="left_thigh_link" />
    <axis
      xyz="0 0 1" />
    <limit
      lower="-3.14"
      upper="3.14"
      effort="0"
      velocity="0" />
  </joint>
  <link
    name="left_shank_link">
    <inertial>
      <origin
        xyz="0.15 5.5511E-17 0.035"
        rpy="0 0 0" />
      <mass
        value="0.50891" />
      <inertia
        ixx="0.00012192"
        ixy="1.3196E-19"
        ixz="-0.00015268"
        iyy="0.0055817"
        iyz="6.6754E-21"
        izz="0.0056477" />
    </inertial>
    <visual>
      <origin
        xyz="0 0 0"
        rpy="0 0 0" />
      <geometry>
        <mesh
          filename="package://Vertical_ver/meshes/left_shank_link.STL" />
      </geometry>
      <material
        name="">
        <color
          rgba="0.89804 0.91765 0.92941 1" />
      </material>
    </visual>
    <collision>
      <origin
        xyz="0 0 0"
        rpy="0 0 0" />
      <geometry>
        <mesh
          filename="package://Vertical_ver/meshes/left_shank_link.STL" />
      </geometry>
    </collision>
  </link>
  <joint
    name="left_knee_joint"
    type="revolute">
    <origin
      xyz="0.3 0 -0.01"
      rpy="0 0 0" />
    <parent
      link="left_thigh_link" />
    <child
      link="left_shank_link" />
    <axis
      xyz="0 0 1" />
    <limit
      lower="-3.14"
      upper="3.14"
      effort="0"
      velocity="0" />
  </joint>
  <link
    name="left_wheel_link">
    <inertial>
      <origin
        xyz="-5.5511E-17 1.3878E-16 0.06"
        rpy="0 0 0" />
      <mass
        value="0.37061" />
      <inertia
        ixx="0.00026155"
        ixy="4.6622E-20"
        ixz="4.2524E-21"
        iyy="0.00026155"
        iyz="9.6334E-21"
        izz="0.0004984" />
    </inertial>
    <visual>
      <origin
        xyz="0 0 0"
        rpy="0 0 0" />
      <geometry>
        <mesh
          filename="package://Vertical_ver/meshes/left_wheel_link.STL" />
      </geometry>
      <material
        name="">
        <color
          rgba="0.89804 0.91765 0.92941 1" />
      </material>
    </visual>
    <collision>
      <origin
        xyz="0 0 0"
        rpy="0 0 0" />
      <geometry>
        <mesh
          filename="package://Vertical_ver/meshes/left_wheel_link.STL" />
      </geometry>
    </collision>
  </link>
  <joint
    name="left_wheel_joint"
    type="continuous">
    <origin
      xyz="0.3 0 0"
      rpy="0 0 0" />
    <parent
      link="left_shank_link" />
    <child
      link="left_wheel_link" />
    <axis
      xyz="0 0 1" />
  </joint>
  <link
    name="right_thigh_link">
    <inertial>
      <origin
        xyz="0.15 -3.7192E-15 0.005"
        rpy="0 0 0" />
      <mass
        value="0.43749" />
      <inertia
        ixx="9.5683E-05"
        ixy="-6.1175E-21"
        ixz="8.096E-22"
        iyy="0.0039485"
        iyz="1.072E-21"
        izz="0.0040369" />
    </inertial>
    <visual>
      <origin
        xyz="0 0 0"
        rpy="0 0 0" />
      <geometry>
        <mesh
          filename="package://Vertical_ver/meshes/right_thigh_link.STL" />
      </geometry>
      <material
        name="">
        <color
          rgba="0.89804 0.91765 0.92941 1" />
      </material>
    </visual>
    <collision>
      <origin
        xyz="0 0 0"
        rpy="0 0 0" />
      <geometry>
        <mesh
          filename="package://Vertical_ver/meshes/right_thigh_link.STL" />
      </geometry>
    </collision>
  </link>
  <joint
    name="right_hip_joint"
    type="revolute">
    <origin
      xyz="0 -0.18 0"
      rpy="1.5708 1.5708 0" />
    <parent
      link="base_link" />
    <child
      link="right_thigh_link" />
    <axis
      xyz="0 0 -1" />
    <limit
      lower="-3.14"
      upper="3.14"
      effort="0"
      velocity="0" />
  </joint>
  <link
    name="right_shank_link">
    <inertial>
      <origin
        xyz="0.15 -2.7756E-17 -0.035"
        rpy="0 0 0" />
      <mass
        value="0.50891" />
      <inertia
        ixx="0.00012192"
        ixy="8.7027E-20"
        ixz="0.00015268"
        iyy="0.0055817"
        iyz="-4.2933E-21"
        izz="0.0056477" />
    </inertial>
    <visual>
      <origin
        xyz="0 0 0"
        rpy="0 0 0" />
      <geometry>
        <mesh
          filename="package://Vertical_ver/meshes/right_shank_link.STL" />
      </geometry>
      <material
        name="">
        <color
          rgba="0.89804 0.91765 0.92941 1" />
      </material>
    </visual>
    <collision>
      <origin
        xyz="0 0 0"
        rpy="0 0 0" />
      <geometry>
        <mesh
          filename="package://Vertical_ver/meshes/right_shank_link.STL" />
      </geometry>
    </collision>
  </link>
  <joint
    name="right_knee_joint"
    type="revolute">
    <origin
      xyz="0.3 0 0.01"
      rpy="0 0 0" />
    <parent
      link="right_thigh_link" />
    <child
      link="right_shank_link" />
    <axis
      xyz="0 0 1" />
    <limit
      lower="-3.14"
      upper="3.14"
      effort="0"
      velocity="0" />
  </joint>
  <link
    name="right_wheel_link">
    <inertial>
      <origin
        xyz="-1.6653E-16 -2.7756E-17 -0.06"
        rpy="0 0 0" />
      <mass
        value="0.37061" />
      <inertia
        ixx="0.00026155"
        ixy="5.6951E-20"
        ixz="-2.3792E-23"
        iyy="0.00026155"
        iyz="5.9823E-21"
        izz="0.0004984" />
    </inertial>
    <visual>
      <origin
        xyz="0 0 0"
        rpy="0 0 0" />
      <geometry>
        <mesh
          filename="package://Vertical_ver/meshes/right_wheel_link.STL" />
      </geometry>
      <material
        name="">
        <color
          rgba="0.89804 0.91765 0.92941 1" />
      </material>
    </visual>
    <collision>
      <origin
        xyz="0 0 0"
        rpy="0 0 0" />
      <geometry>
        <mesh
          filename="package://Vertical_ver/meshes/right_wheel_link.STL" />
      </geometry>
    </collision>
  </link>
  <joint
    name="right_wheel_joint"
    type="continuous">
    <origin
      xyz="0.3 0 0"
      rpy="0 0 0" />
    <parent
      link="right_shank_link" />
    <child
      link="right_wheel_link" />
    <axis
      xyz="0 0 -1" />
  </joint>
</robot>