<?xml version="1.0" encoding="utf-8"?>
<!-- This URDF was automatically created by SolidWorks to URDF Exporter! Originally created by Stephen Brawner (brawner@gmail.com) 
     Commit Version: 1.6.0-4-g7f85cfe  Build Version: 1.6.7995.38578
     For more information, please see http://wiki.ros.org/sw_urdf_exporter -->
<robot
  name="wbr_sim_files_mesh">

  <link name = "foot_print">
    <visual>
        <geometry>
          <sphere radius = "0.005"/>
        </geometry>
    </visual>
  </link>

  <joint name="foot_to_baselink" type="fixed">
    <origin
      xyz="0 0 0.46"
      rpy="0 0 0" />
    <parent
      link="foot_print" />
    <child
      link="base_link" />
  </joint>


  <link
    name="base_link">
    <inertial>
      <origin
        xyz="0 3.4694E-18 -3.4694E-18"
        rpy="0 0 0" />
      <mass
        value="6.9465" />
      <inertia
        ixx="0.024811"
        ixy="1.1952E-18"
        ixz="7.3184E-20"

        iyy="0.019705"
        iyz="-2.7444E-20"

        izz="0.032405" />
    </inertial>
    <visual>
      <origin
        xyz="0 0 0"
        rpy="0 0 0" />
      <geometry>
        <mesh
          filename="package://wbr_sim_files_mesh/meshes/base_link.STL" />
      </geometry>
      <material
        name="">
        <color
          rgba="0.89804 0.91765 0.92941 1" />
      </material>
    </visual>
    <collision>
      <origin
        xyz="0 0 0"
        rpy="0 0 0" />
      <geometry>
        <mesh
          filename="package://wbr_sim_files_mesh/meshes/base_link.STL" />
      </geometry>
    </collision>

  </link>


  <link
    name="Left_thigh_link">
    <inertial>
      <origin
        xyz="0.1 0 0.0175"
        rpy="0 0 0" />
      <mass
        value="2.258" />
      <inertia
        ixx="0.0020663"
        ixy="-5.2292E-20"
        ixz="-6.4586E-21"
        iyy="0.014683"
        iyz="0"
        izz="0.016288" />
    </inertial>
    <visual>
      <origin
        xyz="0 0 0"
        rpy="0 0 0" />
      <geometry>
        <mesh
          filename="package://wbr_sim_files_mesh/meshes/Left_thigh_link.STL" />
      </geometry>
      <material
        name="">
        <color
          rgba="0.84706 0.84706 0.84706 1" />
      </material>
    </visual>
    <collision>
      <origin
        xyz="0 0 0"
        rpy="0 0 0" />
      <geometry>
        <mesh
          filename="package://wbr_sim_files_mesh/meshes/Left_thigh_link.STL" />
      </geometry>
    </collision>
  </link>

  <joint
    name="Left_hip_joint"
    type="revolute">
    <origin
      xyz="0 0.09 0"
      rpy="-1.5708 1.5708 0" />
      <!-- ????? -->
    <parent
      link="base_link" />
    <child
      link="Left_thigh_link" />
    <axis
      xyz="0 0 1" />
    <limit
      lower="-3.14"
      upper="3.14"
      effort="50"
      velocity="30" />
  </joint>
  <link
    name="Left_shank_link">
    <inertial>
      <origin
        xyz="0.09 2.7756E-17 0.0175"
        rpy="0 0 0" />
      <mass
        value="2.0872" />
      <inertia
        ixx="0.0019065"
        ixy="-9.6032E-19"
        ixz="2.0291E-20"
        iyy="0.011793"
        iyz="9.7758E-21"
        izz="0.013273" />
    </inertial>
    <visual>
      <origin
        xyz="0 0 0"
        rpy="0 0 0" />
      <geometry>
        <mesh
          filename="package://wbr_sim_files_mesh/meshes/Left_shank_link.STL" />
      </geometry>
      <material
        name="">
        <color
          rgba="0.84706 0.84706 0.84706 1" />
      </material>
    </visual>
    <collision>
      <origin
        xyz="0 0 0"
        rpy="0 0 0" />
      <geometry>
        <mesh
          filename="package://wbr_sim_files_mesh/meshes/Left_shank_link.STL" />
      </geometry>
    </collision>
  </link>
  <joint
    name="Left_knee_joint"
    type="revolute">
    <origin
      xyz="0.2 0 0.035"
      rpy="0 0 0" />
    <parent
      link="Left_thigh_link" />
    <child
      link="Left_shank_link" />
    <axis
      xyz="0 0 1" />
    <limit
      lower="-3.14"
      upper="3.14"
      effort="50"
      velocity="30" />
  </joint>
  <link
    name="Left_wheel_link">
    <inertial>
      <origin
        xyz="0 0 0.0175"
        rpy="0 0 0" />
      <mass
        value="1.6567" />
      <inertia
        ixx="0.002913"
        ixy="-2.407E-20"
        ixz="-4.8224E-21"
        iyy="0.002913"
        iyz="2.5619E-21"
        izz="0.0054878" />
    </inertial>
    <visual>
      <origin
        xyz="0 0 0"
        rpy="0 0 0" />
      <geometry>
        <mesh
          filename="package://wbr_sim_files_mesh/meshes/Left_wheel_link.STL" />
      </geometry>
      <material
        name="">
        <color
          rgba="0.84706 0.84706 0.84706 1" />
      </material>
    </visual>
    <collision>
      <origin
        xyz="0 0 0"
        rpy="0 0 0" />
      <geometry>
        <mesh
          filename="package://wbr_sim_files_mesh/meshes/Left_wheel_link.STL" />
      </geometry>
    </collision>
  </link>
  <joint
    name="Left_wheel_joint"
    type="continuous">
    <origin
      xyz="0.18 0 0.035"
      rpy="0 0 0" />
    <parent
      link="Left_shank_link" />
    <child
      link="Left_wheel_link" />
    <axis
      xyz="0 0 1" />
  </joint>
  <link
    name="Right_thigh_link">
    <inertial>
      <origin
        xyz="0.1 0 -0.0175"
        rpy="0 0 0" />
      <mass
        value="2.258" />
      <inertia
        ixx="0.0020663"
        ixy="-5.2292E-20"
        ixz="-6.4586E-21"
        iyy="0.014683"
        iyz="0"
        izz="0.016288" />
    </inertial>
    <visual>
      <origin
        xyz="0 0 0"
        rpy="0 0 0" />
      <geometry>
        <mesh
          filename="package://wbr_sim_files_mesh/meshes/Right_thigh_link.STL" />
      </geometry>
      <material
        name="">
        <color
          rgba="1 1 1 1" />
      </material>
    </visual>
    <collision>
      <origin
        xyz="0 0 0"
        rpy="0 0 0" />
      <geometry>
        <mesh
          filename="package://wbr_sim_files_mesh/meshes/Right_thigh_link.STL" />
      </geometry>
    </collision>
  </link>
  <joint
    name="Right_hip_joint"
    type="revolute">
    <origin
      xyz="0 -0.09 0"
      rpy="-1.5708 1.5708 0" />
    <parent
      link="base_link" />
    <child
      link="Right_thigh_link" />
    <axis
      xyz="0 0 1" />
    <limit
      lower="-3.14"
      upper="3.14"
      effort="50"
      velocity="30" />
  </joint>
  <link
    name="Right_shank_link">
    <inertial>
      <origin
        xyz="0.09 5.5511E-17 -0.0175"
        rpy="0 0 0" />
      <mass
        value="2.0872" />
      <inertia
        ixx="0.0019065"
        ixy="-7.382E-19"
        ixz="-4.9947E-20"
        iyy="0.011793"
        iyz="-1.7781E-20"
        izz="0.013273" />
    </inertial>
    <visual>
      <origin
        xyz="0 0 0"
        rpy="0 0 0" />
      <geometry>
        <mesh
          filename="package://wbr_sim_files_mesh/meshes/Right_shank_link.STL" />
      </geometry>
      <material
        name="">
        <color
          rgba="0.84706 0.84706 0.84706 1" />
      </material>
    </visual>
    <collision>
      <origin
        xyz="0 0 0"
        rpy="0 0 0" />
      <geometry>
        <mesh
          filename="package://wbr_sim_files_mesh/meshes/Right_shank_link.STL" />
      </geometry>
    </collision>
  </link>
  <joint
    name="Right_knee_joint"
    type="revolute">
    <origin
      xyz="0.2 0 -0.035"
      rpy="0 0 0" />
    <parent
      link="Right_thigh_link" />
    <child
      link="Right_shank_link" />
    <axis
      xyz="0 0 1" />
    <limit
      lower="-3.14"
      upper="3.14"
      effort="50"
      velocity="30" />
  </joint>
  <link
    name="Right_wheel_link">
    <inertial>
      <origin
        xyz="0 -2.7756E-17 -0.0175"
        rpy="0 0 0" />
      <mass
        value="1.6567" />
      <inertia
        ixx="0.002913"
        ixy="0"
        ixz="4.8088E-36"
        iyy="0.002913"
        iyz="-7.283E-35"
        izz="0.0054878" />
    </inertial>
    <visual>
      <origin
        xyz="0 0 0"
        rpy="0 0 0" />
      <geometry>
        <mesh
          filename="package://wbr_sim_files_mesh/meshes/Right_wheel_link.STL" />
      </geometry>
      <material
        name="">
        <color
          rgba="0.84706 0.84706 0.84706 1" />
      </material>
    </visual>
    <collision>
      <origin
        xyz="0 0 0"
        rpy="0 0 0" />
      <geometry>
        <mesh
          filename="package://wbr_sim_files_mesh/meshes/Right_wheel_link.STL" />
      </geometry>
    </collision>
  </link>
  <joint
    name="Right_wheel_joint"
    type="continuous">
    <origin
      xyz="0.18 0 -0.035"
      rpy="0 0 0" />
    <parent
      link="Right_shank_link" />
    <child
      link="Right_wheel_link" />
    <axis
      xyz="0 0 1" />
  </joint>
</robot>